Workbook

Sheet Datos
A1: Seg Horario | B1: Hora de pedido | C1: Tipo de pedido | D1: Tipo de Establecimiento | E1: ID | F1: Doblete | G1: ID | H1: Monto | I1: TARIFA | J1: RAPPI RECOMPENSA | K1: PROPINA | L1: KM | M1: Fecha | N1: DIA | O1: DIA TEXTO | P1: MES | Q1: MES TEXTO | R1: EFECTIVO | S1: MONTO EFECTIVO | T1: Lluvia
A2: 4 | B2: 6:39 a. m. | C2: Restaurante | D2: Groovy Cookies | H2: 1910 | M2: 45863 | N2: =DAY(M2) -> 25 | O2: =TEXT(M2,"DDDD") -> viernes | P2: =MONTH(M2) -> 7 | Q2: =TEXT(M2,"MMMM") -> julio
A3: 4 | B3: 5:49 a. m. | C3: Restaurante | D3: Cümen Cümen | H3: 2350 | M3: 45863 | N3: =DAY(M3) -> 25 | O3: =TEXT(M3,"DDDD") -> viernes | P3: =MONTH(M3) -> 7 | Q3: =TEXT(M3,"MMMM") -> julio
A4: 1 | B4: 1:53 a. m. | C4: Restaurante | D4: ELC - McDonald's | H4: 2481 | M4: 45863 | N4: =DAY(M4) -> 25 | O4: =TEXT(M4,"DDDD") -> viernes | P4: =MONTH(M4) -> 7 | Q4: =TEXT(M4,"MMMM") -> julio
A5: 1 | B5: 1:37 a. m. | C5: Restaurante | D5: COL - McDonald's | H5: 2141 | M5: 45863 | N5: =DAY(M5) -> 25 | O5: =TEXT(M5,"DDDD") -> viernes | P5: =MONTH(M5) -> 7 | Q5: =TEXT(M5,"MMMM") -> julio
A6: 1 | B6: 1:21 a. m. | C6: Restaurante | D6: Tea Connection | H6: 3260 | M6: 45863 | N6: =DAY(M6) -> 25 | O6: =TEXT(M6,"DDDD") -> viernes | P6: =MONTH(M6) -> 7 | Q6: =TEXT(M6,"MMMM") -> julio
A7: 1 | B7: 1:11 a. m. | C7: Restaurante | D7: DIA Palermo | H7: 2610 | M7: 45863 | N7: =DAY(M7) -> 25 | O7: =TEXT(M7,"DDDD") -> viernes | P7: =MONTH(M7) -> 7 | Q7: =TEXT(M7,"MMMM") -> julio
A8: 1 | B8: 12:56 a. m. | C8: Restaurante | D8: DIA Envío Rápido | H8: 5475 | M8: 45863 | N8: =DAY(M8) -> 25 | O8: =TEXT(M8,"DDDD") -> viernes | P8: =MONTH(M8) -> 7 | Q8: =TEXT(M8,"MMMM") -> julio
A9: 5 | B9: 9:49 a. m. | C9: Restaurante | D9: Rock and Ribs | F9: Green Eat - Sinclair | H9: 3430 | I9: 2710 | K9: 600 | M9: 45866 | N9: =DAY(M9) -> 28 | O9: =TEXT(M9,"DDDD") -> lunes | P9: =MONTH(M9) -> 7 | Q9: =TEXT(M9,"MMMM") -> julio
A10: 5 | B10: 9:31 a. m. | C10: Super/Tienda | D10: PIZZA DATA | H10: 2960 | I10: 1400 | K10: 1500 | M10: 45866 | N10: =DAY(M10) -> 28 | O10: =TEXT(M10,"DDDD") -> lunes | P10: =MONTH(M10) -> 7 | Q10: =TEXT(M10,"MMMM") -> julio
A11: 5 | B11: 9:02 a. m. | C11: Super/Tienda | D11: DIA Envío Rápido, cerviño (523) | F11: DIA Envío Rápido, cerviño (523) | H11: 4710 | I11: 3250 | J11: 40 | K11: 1300 | M11: 45866 | N11: =DAY(M11) -> 28 | O11: =TEXT(M11,"DDDD") -> lunes | P11: =MONTH(M11) -> 7 | Q11: =TEXT(M11,"MMMM") -> julio
A12: 5 | B12: 8:29 a. m. | C12: Super/Tienda | D12: Carrefour Hiper, Salguero (6) | H12: 5100 | I12: 3540 | K12: 1460 | M12: 45866 | N12: =DAY(M12) -> 28 | O12: =TEXT(M12,"DDDD") -> lunes | P12: =MONTH(M12) -> 7 | Q12: =TEXT(M12,"MMMM") -> julio
A13: 5 | B13: 8:10 a. m. | C13: Super/Tienda | D13: Armando Florería | H13: 2030 | I13: 1220 | K13: 750 | M13: 45866 | N13: =DAY(M13) -> 28 | O13: =TEXT(M13,"DDDD") -> lunes | P13: =MONTH(M13) -> 7 | Q13: =TEXT(M13,"MMMM") -> julio
A14: 4 | B14: 6:51 a. m. | C14: Restaurante | D14: McDonald's - SF6 int | F14: McDonald's - SF6 int | H14: 2120 | I14: 1800 | K14: 200 | M14: 45866 | N14: =DAY(M14) -> 28 | O14: =TEXT(M14,"DDDD") -> lunes | P14: =MONTH(M14) -> 7 | Q14: =TEXT(M14,"MMMM") -> julio
A15: 4 | B15: 7:05 a. m. | C15: Restaurante | D15: Rappi Favor, Bs As CABA (Balvanera/Once) | H15: 1610 | M15: 45866 | N15: =DAY(M15) -> 28 | O15: =TEXT(M15,"DDDD") -> lunes | P15: =MONTH(M15) -> 7 | Q15: =TEXT(M15,"MMMM") -> julio
A16: 12 | B16: 10:36 p. m. | C16: Restaurante | D16: Los Maestros - recoleta | F16: Los Maestros - recoleta | H16: 3120 | M16: 45867 | N16: =DAY(M16) -> 29 | O16: =TEXT(M16,"DDDD") -> martes | P16: =MONTH(M16) -> 7 | Q16: =TEXT(M16,"MMMM") -> julio
A17: 12 | B17: 10:03 p. m. | C17: Super/Tienda | D17: Freddo - Ayacucho | H17: 1940 | I17: 1200 | K17: 680 | M17: 45867 | N17: =DAY(M17) -> 29 | O17: =TEXT(M17,"DDDD") -> martes | P17: =MONTH(M17) -> 7 | Q17: =TEXT(M17,"MMMM") -> julio
A18: 11 | B18: 8:58 p. m. | C18: Super/Tienda | D18: Rappi Favor, Bs As CABA (Villa Crespo/Chacarita) | H18: 1470 | I18: 1410 | J18: 60 | M18: 45867 | N18: =DAY(M18) -> 29 | O18: =TEXT(M18,"DDDD") -> martes | P18: =MONTH(M18) -> 7 | Q18: =TEXT(M18,"MMMM") -> julio
A19: 11 | B19: 8:27 p. m. | C19: Super/Tienda | D19: Faricci - Palermo | H19: 3400 | M19: 45867 | N19: =DAY(M19) -> 29 | O19: =TEXT(M19,"DDDD") -> martes | P19: =MONTH(M19) -> 7 | Q19: =TEXT(M19,"MMMM") -> julio
A20: 11 | B20: 8:18 p. m. | C20: Super/Tienda | D20: Tu Arepa Aguero | H20: 1260 | I20: 1200 | J20: 60 | M20: 45867 | N20: =DAY(M20) -> 29 | O20: =TEXT(M20,"DDDD") -> martes | P20: =MONTH(M20) -> 7 | Q20: =TEXT(M20,"MMMM") -> julio
A21: 9 | B21: 4:36 p. m. | C21: Restaurante | D21: Rincón Norteño - Parque Las Heras | H21: 2500 | I21: 1200 | K21: 1240 | M21: 45867 | N21: =DAY(M21) -> 29 | O21: =TEXT(M21,"DDDD") -> martes | P21: =MONTH(M21) -> 7 | Q21: =TEXT(M21,"MMMM") -> julio
A22: 9 | B22: 4:10 p. m. | C22: Super/Tienda | D22: Fullser24hs Palermo | H22: 1860 | I22: 1200 | K22: 600 | M22: 45867 | N22: =DAY(M22) -> 29 | O22: =TEXT(M22,"DDDD") -> martes | P22: =MONTH(M22) -> 7 | Q22: =TEXT(M22,"MMMM") -> julio
A23: 9 | B23: 7:37 p. m. | C23: Super/Tienda | D23: Coto, -158 Charcas | H23: 1260 | I23: 1200 | J23: 60 | M23: 45867 | N23: =DAY(M23) -> 29 | O23: =TEXT(M23,"DDDD") -> martes | P23: =MONTH(M23) -> 7 | Q23: =TEXT(M23,"MMMM") -> julio
A24: 9 | B24: 7:23 p. m. | C24: Restaurante | D24: Open Market, AV. Pueyrredon 1298 (964) | H24: 2360 | I24: 1200 | K24: 1100 | M24: 45867 | N24: =DAY(M24) -> 29 | O24: =TEXT(M24,"DDDD") -> martes | P24: =MONTH(M24) -> 7 | Q24: =TEXT(M24,"MMMM") -> julio
A25: 9 | B25: 6:47 p. m. | C25: Super/Tienda | D25: Cremolatti - Santa Fe | H25: 2820 | I25: 1200 | K25: 1560 | M25: 45867 | N25: =DAY(M25) -> 29 | O25: =TEXT(M25,"DDDD") -> martes | P25: =MONTH(M25) -> 7 | Q25: =TEXT(M25,"MMMM") -> julio
A26: 9 | B26: 6:33 p. m. | C26: Restaurante | D26: Coto, -158 Charcas | H26: 5850 | I26: 4700 | J26: 40 | K26: 1050 | M26: 45867 | N26: =DAY(M26) -> 29 | O26: =TEXT(M26,"DDDD") -> martes | P26: =MONTH(M26) -> 7 | Q26: =TEXT(M26,"MMMM") -> julio
A27: 8 | B27: 3:36 p. m. | C27: Super/Tienda | D27: Sake Sushi Delivery | H27: 2860 | I27: 1200 | K27: 1600 | M27: 45867 | N27: =DAY(M27) -> 29 | O27: =TEXT(M27,"DDDD") -> martes | P27: =MONTH(M27) -> 7 | Q27: =TEXT(M27,"MMMM") -> julio
A28: 8 | B28: 3:02 p. m. | C28: Super/Tienda | D28: Burgertify - Recoleta | H28: 2280 | I28: 1200 | K28: 1020 | M28: 45867 | N28: =DAY(M28) -> 29 | O28: =TEXT(M28,"DDDD") -> martes | P28: =MONTH(M28) -> 7 | Q28: =TEXT(M28,"MMMM") -> julio
A29: 8 | B29: 2:26 p. m. | C29: Restaurante | D29: SushiPop - Las Heras | H29: 2760 | I29: 1200 | K29: 1500 | M29: 45867 | N29: =DAY(M29) -> 29 | O29: =TEXT(M29,"DDDD") -> martes | P29: =MONTH(M29) -> 7 | Q29: =TEXT(M29,"MMMM") -> julio
A30: 7 | B30: 1:48 p. m. | C30: Restaurante | D30: The Food Truck - PALERMO | F30: Fabric Sushi Barrio Norte | H30: 2570 | I30: 2450 | M30: 45867 | N30: =DAY(M30) -> 29 | O30: =TEXT(M30,"DDDD") -> martes | P30: =MONTH(M30) -> 7 | Q30: =TEXT(M30,"MMMM") -> julio
A31: 11 | B31: 8:05 p.m. | C31: Panadería | D31: McDonald's - SF3 int | F31: McDonald's - SF3 int | H31: 1920 | I31: 1800 | M31: 45868 | N31: =DAY(M31) -> 30 | O31: =TEXT(M31,"DDDD") -> miércoles | P31: =MONTH(M31) -> 7 | Q31: =TEXT(M31,"MMMM") -> julio | R31: efectivo | S31: 19692
A32: 9 | B32: 6:11 p. m. | C32: Super/Tienda | D32: McDonald's - SF5 int | F32: McDonald's - SF5 int | H32: 2720 | I32: 2100 | K32: 500 | M32: 45868 | N32: =DAY(M32) -> 30 | O32: =TEXT(M32,"DDDD") -> miércoles | P32: =MONTH(M32) -> 7 | Q32: =TEXT(M32,"MMMM") -> julio
A33: 8 | B33: 5:50 p. m. | C33: Super/Tienda | D33: Turbo, Palermo 1 | H33: 2470 | I33: 2050 | K33: 360 | M33: 45868 | N33: =DAY(M33) -> 30 | O33: =TEXT(M33,"DDDD") -> miércoles | P33: =MONTH(M33) -> 7 | Q33: =TEXT(M33,"MMMM") -> julio
A34: 8 | B34: 5:20 p. m. | C34: Restaurante | D34: McDonald's - CPY int | H34: 2060 | I34: 1200 | K34: 800 | M34: 45868 | N34: =DAY(M34) -> 30 | O34: =TEXT(M34,"DDDD") -> miércoles | P34: =MONTH(M34) -> 7 | Q34: =TEXT(M34,"MMMM") -> julio
A35: 8 | B35: 4:54 p. m. | C35: Restaurante | D35: McDonald's - SF3 int | H35: 2640 | I35: 1200 | K35: 1380 | M35: 45868 | N35: =DAY(M35) -> 30 | O35: =TEXT(M35,"DDDD") -> miércoles | P35: =MONTH(M35) -> 7 | Q35: =TEXT(M35,"MMMM") -> julio | R35: efectivo | S35: 29719.5
A36: 8 | B36: 4:21 p. m. | C36: Super/Tienda | D36: McDonald's - SF3 int | H36: 2520 | I36: 1200 | K36: 1260 | M36: 45868 | N36: =DAY(M36) -> 30 | O36: =TEXT(M36,"DDDD") -> miércoles | P36: =MONTH(M36) -> 7 | Q36: =TEXT(M36,"MMMM") -> julio
A37: 9 | B37: 7:01 p.m. | C37: Super/Tienda | D37: KFC - Pueyrredón - Turbo | H37: 1960 | I37: 1200 | K37: 700 | M37: 45870 | N37: =DAY(M37) -> 1 | O37: =TEXT(M37,"DDDD") -> viernes | P37: =MONTH(M37) -> 8 | Q37: =TEXT(M37,"MMMM") -> agosto
A38: 9 | B38: 6:38 p.m. | C38: Restaurante | D38: Pan de Queso Brasil - Almagro | F38: Grido Once | H38: 3500 | I38: 2100 | K38: 1280 | M38: 45870 | N38: =DAY(M38) -> 1 | O38: =TEXT(M38,"DDDD") -> viernes | P38: =MONTH(M38) -> 8 | Q38: =TEXT(M38,"MMMM") -> agosto
A39: 9 | B39: 6:05 p.m. | C39: Restaurante | D39: Disco, Santa Fe(22) | H39: 3500 | I39: 2840 | K39: 600 | M39: 45870 | N39: =DAY(M39) -> 1 | O39: =TEXT(M39,"DDDD") -> viernes | P39: =MONTH(M39) -> 8 | Q39: =TEXT(M39,"MMMM") -> agosto
A40: 8 | B40: 5:46 p.m. | C40: Super/Tienda | D40: Coto, -158 Charcas | H40: 4400 | I40: 3680 | J40: 40 | K40: 620 | M40: 45870 | N40: =DAY(M40) -> 1 | O40: =TEXT(M40,"DDDD") -> viernes | P40: =MONTH(M40) -> 8 | Q40: =TEXT(M40,"MMMM") -> agosto
...

Sheet Resumen_por_dia
A1: Fecha | B1: Total_Ingresos | C1: Cant_Pedidos | D1: DOBLETE | E1: Cantidad total Pedidios | F1: DIA | G1: Ticket_Promedio(No tiene en cuenta doblete) | I1: Seg Horario 1 | J1: Seg Horario 2 | K1: Seg Horario 3 | L1: Seg Horario 4 | M1: Seg Horario 5 | N1: Seg Horario 6 | O1: Seg Horario 7 | P1: Seg Horario 8 | Q1: Seg Horario 9 | R1: Seg Horario 10 | S1: Seg Horario 11 | T1: Seg Horario 12
A2: 45863 | B2: =SUM(Datos!H2:H8) -> 20227 | C2: =COUNTA(Datos!H2:H8) -> 7 | F2: Viernes | G2: =AVERAGE(Datos!H2:H8) -> 2889.5714 | I2: 1 | J2: 0 | K2: 0 | L2: 1 | M2: 0 | N2: 0 | O2: 0 | P2: 0 | Q2: 0 | R2: 0 | S2: 0 | T2: 0
A3: 45866 | B3: =SUM(Datos!H9:H15) -> 21960 | C3: =COUNTA(Datos!H9:H15) -> 7 | D3: 3 | E3: =SUM(C3+D3) -> 10 | F3: Lunes | G3: =AVERAGE(Datos!H9:H15) -> 3137.1429 | I3: 0 | J3: 0 | K3: 0 | L3: 1 | M3: 1 | N3: 0 | O3: 0 | P3: 0 | Q3: 0 | R3: 0 | S3: 0 | T3: 0
A4: 45867 | B4: =SUM(Datos!H16:H30) -> 38310 | C4: =COUNTA(Datos!H16:H30) -> 15 | D4: 2 | E4: =SUM(C4+D4) -> 17 | F4: Martes | G4: =AVERAGE(Datos!H16:H30) -> 2554 | I4: 0 | J4: 0 | K4: 0 | L4: 0 | M4: 0 | N4: 0 | O4: 1 | P4: 1 | Q4: 1 | R4: 0 | S4: 1 | T4: 1
A5: 45868 | B5: =SUM(Datos!H31:H36) -> 14330 | C5: =COUNTA(Datos!H31:H36) -> 6 | D5: 2 | E5: =SUM(C5+D5) -> 8 | F5: Miercoles | G5: =AVERAGE(Datos!H31:H36) -> 2388.3333 | I5: 0 | J5: 0 | K5: 0 | L5: 0 | M5: 0 | N5: 0 | O5: 0 | P5: 1 | Q5: 1 | R5: 0 | S5: 1 | T5: 0
A6: 45870 | B6: =SUM(Datos!H114:H128) -> 40900 | C6: =COUNTA(Datos!H114:H128) -> 15 | D6: 2 | E6: =SUM(C6+D6) -> 17 | F6: Viernes | G6: =AVERAGE(Datos!H114:H128) -> 2726.6667 | I6: 0 | J6: 0 | K6: 0 | L6: 0 | M6: 0 | N6: 1 | O6: 1 | P6: 1 | Q6: 1 | R6: 0 | S6: 0 | T6: 0
A7: 45871 | B7: =SUM(Datos!H52:H69) -> 61330 | C7: =COUNTA(Datos!H52:H69) -> 18 | D7: 5 | E7: =SUM(C7+D7) -> 23 | F7: Sabado | G7: =AVERAGE(Datos!H52:H69) -> 3407.2222 | I7: 0 | J7: 0 | K7: 0 | L7: 0 | M7: 0 | N7: 0 | O7: 0 | P7: 1 | Q7: 0 | R7: 1 | S7: 1 | T7: 1
A8: 45872 | B8: =SUM(Datos!H70:H79) -> 24830 | C8: =COUNTA(Datos!H70:H79) -> 10 | D8: 1 | E8: =SUM(C8+D8) -> 11 | F8: Domingo | G8: =AVERAGE(Datos!H70:H79) -> 2483 | I8: 0 | J8: 0 | K8: 0 | L8: 0 | M8: 0 | N8: 0 | O8: 1 | P8: 1 | Q8: 1 | R8: 1 | S8: 1 | T8: 0
A9: 45875 | B9: =SUM(Datos!H80:H92) -> 26605 | C9: =COUNTA(Datos!H80:H92) -> 13 | D9: 1 | E9: =SUM(C9+D9) -> 14 | F9: Miercoles | G9: =AVERAGE(Datos!H80:H92) -> 2046.5385 | I9: 1 | J9: 1 | K9: 1 | L9: 0 | M9: 0 | N9: 0 | O9: 0 | P9: 0 | Q9: 1 | R9: 0 | S9: 0 | T9: 0
A10: 45877 | B10: =SUM(Datos!H93:H101) -> 15435 | C10: =COUNTA(Datos!H93:H101) -> 9 | D10: 0 | E10: =SUM(C10+D10) -> 9 | F10: Viernes | G10: =AVERAGE(Datos!H93:H101) -> 1715 | I10: 1 | J10: 1 | K10: 1 | L10: 1 | M10: 0 | N10: 0 | O10: 0 | P10: 0 | Q10: 0 | R10: 0 | S10: 0 | T10: 0
A11: 45878 | B11: =SUM(Datos!H102:H116) -> 31841 | C11: =COUNTA(Datos!H102:H116) -> 15 | D11: 0 | E11: =SUM(C11+D11) -> 15 | F11: Sabado | G11: =AVERAGE(Datos!H102:H116) -> 2122.7333 | I11: 0 | J11: 0 | K11: 0 | L11: 0 | M11: 0 | N11: 0 | O11: 0 | P11: 0 | Q11: 1 | R11: 1 | S11: 1 | T11: 0
A12: 45879 | B12: =SUM(Datos!H117:H140) -> 61893.88 | C12: =COUNTA(Datos!H117:H140) -> 23 | D12: 6 | E12: =SUM(C12+D12) -> 29 | F12: Domingo | G12: =AVERAGE(Datos!H117:H140) -> 2691.0383 | I12: 1 | J12: 1 | K12: 1 | L12: 0 | M12: 0 | N12: 0 | O12: 0 | P12: 1 | Q12: 1 | R12: 1 | S12: 1 | T12: 1
A13: 45884 | B13: =SUM(Datos!H141:H150) -> 22640 | C13: =COUNTA(Datos!H141:H150) -> 10 | D13: 0 | E13: =SUM(C13+D13) -> 10 | F13: Viernes | G13: =AVERAGE(Datos!H141:H150) -> 2264 | I13: 0 | J13: 1 | K13: 0 | L13: 0 | M13: 0 | N13: 0 | O13: 0 | P13: 0 | Q13: 0 | R13: 0 | S13: 1 | T13: 1
A14: 45885 | B14: =SUM(Datos!H151:H157) -> 21470 | C14: =COUNTA(Datos!H151:H157) -> 7 | D14: 0 | E14: =SUM(C14+D14) -> 7 | F14: Sabado | G14: =AVERAGE(Datos!H151:H157) -> 3067.1429 | I14: 1 | J14: 1 | K14: 1 | L14: 0 | M14: 0 | N14: 0 | O14: 0 | P14: 0 | Q14: 0 | R14: 0 | S14: 0 | T14: 0
A15: 45889 | B15: =SUM(Datos!H158:H171) -> 33631 | C15: =COUNTA(Datos!H158:H171) -> 14 | D15: 0 | E15: =SUM(C15+D15) -> 14 | F15: Miercoles | G15: =AVERAGE(Datos!H158:H171) -> 2402.2143 | I15: 1 | J15: 1 | K15: 0 | L15: 0 | M15: 0 | N15: 0 | O15: 0 | P15: 0 | Q15: 1 | R15: 1 | S15: 0 | T15: 1
A16: 45890 | B16: =SUM(Datos!H172:H191) -> 42841 | C16: =COUNTA(Datos!H172:H191) -> 20 | D16: 0 | E16: =SUM(C16+D16) -> 20 | F16: Jueves | G16: =AVERAGE(Datos!H172:H191) -> 2142.05 | I16: 1 | J16: 1 | K16: 1 | L16: 0 | M16: 1 | N16: 1 | O16: 0 | P16: 0 | Q16: 1 | R16: 0 | S16: 1 | T16: 1
A17: 45893 | B17: =SUM(Datos!H192:H223) -> 99390 | C17: =COUNTA(Datos!H192:H223) -> 32 | D17: 7 | E17: =SUM(C17+D17) -> 39 | F17: Domingo | G17: =AVERAGE(Datos!H192:H223) -> 3105.9375 | I17: 0 | J17: 0 | K17: 0 | L17: 1 | M17: 1 | N17: 0 | O17: 1 | P17: 1 | Q17: 1 | R17: 1 | S17: 1 | T17: 1
A18: 45896 | B18: =SUM(Datos!H224:H239) -> 36375 | C18: =COUNTA(Datos!H224:H239) -> 16 | D18: 3 | E18: =SUM(C18+D18) -> 19 | F18: Miercoles | G18: =AVERAGE(Datos!H224:H239) -> 2273.4375 | I18: 0 | J18: 0 | K18: 0 | L18: 0 | M18: 0 | N18: 0 | O18: 0 | P18: 1 | Q18: 1 | R18: 1 | S18: 1 | T18: 1
A19: 45900 | B19: =SUM(Datos!H240:H255) -> 45700 | C19: =COUNTA(Datos!H240:H255) -> 16 | D19: 0 | E19: =SUM(C19+D19) -> 16 | F19: Domingo | G19: =AVERAGE(Datos!H240:H255) -> 2856.25 | I19: 0 | J19: 0 | K19: 1 | L19: 1 | M19: 0 | N19: 0 | O19: 1 | P19: 1 | Q19: 1 | R19: 1 | S19: 1 | T19: 0
A20: 45901 | B20: =SUM(Datos!H256:H264) -> 24670 | C20: =COUNTA(Datos!H256:H264) -> 9 | D20: 4 | E20: =SUM(C20+D20) -> 13 | F20: Lunes | G20: =AVERAGE(Datos!H256:H264) -> 2741.1111 | I20: 0 | J20: 0 | K20: 0 | L20: 0 | M20: 0 | N20: 0 | O20: 0 | P20: 1 | Q20: 1 | R20: 1 | S20: 0 | T20: 1
A21: 45902 | B21: =SUM(Datos!H265:H272) -> 19558 | C21: =COUNTA(Datos!H265:H272) -> 8 | D21: 1 | E21: =SUM(C21+D21) -> 9 | F21: Martes | G21: =AVERAGE(Datos!H265:H272) -> 2444.75 | I21: 1 | J21: 1 | K21: 1 | L21: 0 | M21: 0 | N21: 0 | O21: 0 | P21: 0 | Q21: 0 | R21: 0 | S21: 0 | T21: 0
A22: 45903 | B22: =SUM(Datos!H273:H280) -> 14536 | C22: =COUNTA(Datos!H273:H280) -> 8 | D22: 0 | E22: =SUM(C22+D22) -> 8 | F22: Miercoles | G22: =AVERAGE(Datos!H273:H280) -> 1817 | I22: 0 | J22: 0 | K22: 0 | L22: 0 | M22: 1 | N22: 1 | O22: 1 | P22: 0 | Q22: 0 | R22: 0 | S22: 0 | T22: 0
A23: 45904 | B23: =SUM(Datos!H281:H289) -> 16510 | C23: =COUNTA(Datos!H281:H289) -> 9 | D23: 2 | E23: =SUM(C23+D23) -> 11 | F23: Jueves | G23: =AVERAGE(Datos!H281:H289) -> 1834.4444 | I23: 0 | J23: 0 | K23: 0 | L23: 0 | M23: 0 | N23: 0 | O23: 0 | P23: 0 | Q23: 0 | R23: 1 | S23: 1 | T23: 1
A24: 45905 | B24: =SUM(Datos!H290:H297) -> 27510 | C24: =COUNTA(Datos!H290:H297) -> 8 | D24: 2 | E24: =SUM(C24+D24) -> 10 | F24: Viernes | G24: =AVERAGE(Datos!H290:H297) -> 3438.75 | I24: 0 | J24: 0 | K24: 0 | L24: 0 | M24: 0 | N24: 0 | O24: 0 | P24: 1 | Q24: 1 | R24: 1 | S24: 0 | T24: 1
A25: 45906 | B25: =SUM(Datos!H298:H308) -> 24060 | C25: =COUNTA(Datos!H298:H308) -> 11 | D25: 1 | E25: =SUM(C25+D25) -> 12 | F25: Sabado | G25: =AVERAGE(Datos!H298:H308) -> 2187.2727 | I25: 1 | J25: 1 | K25: 1 | L25: 0 | M25: 0 | N25: 0 | O25: 0 | P25: 0 | Q25: 0 | R25: 0 | S25: 0 | T25: 0
A26: 45907 | B26: =SUM(Datos!H309:H311) -> 7441 | C26: =COUNTA(Datos!H309:H311) -> 3 | D26: 2 | E26: =SUM(C26+D26) -> 5 | F26: Domingo | G26: =AVERAGE(Datos!H309:H311) -> 2480.3333 | I26: 0 | J26: 0 | K26: 0 | L26: 0 | M26: 0 | N26: 0 | O26: 0 | P26: 0 | Q26: 0 | R26: 0 | S26: 0 | T26: 1
A27: 45908 | B27: =SUM(Datos!H312:H316) -> 11320 | C27: =COUNTA(Datos!H312:H316) -> 5 | D27: 1 | E27: =SUM(C27+D27) -> 6 | F27: Lunes | G27: =AVERAGE(Datos!H312:H316) -> 2264 | I27: 1 | J27: 1 | K27: 0 | L27: 0 | M27: 0 | N27: 0 | O27: 0 | P27: 0 | Q27: 0 | R27: 0 | S27: 0 | T27: 0
A28: 45909 | B28: =SUM(Datos!H317:H322) -> 12850 | C28: =COUNTA(Datos!H317:H322) -> 6 | D28: 0 | E28: =SUM(C28+D28) -> 6 | F28: Martes | G28: =AVERAGE(Datos!H317:H322) -> 2141.6667 | I28: 0 | J28: 0 | K28: 0 | L28: 1 | M28: 1 | N28: 0 | O28: 0 | P28: 0 | Q28: 0 | R28: 0 | S28: 0 | T28: 0
A29: 45910 | B29: =SUM(Datos!H323:H331) -> 17690 | C29: =COUNTA(Datos!H323:H331) -> 9 | D29: 1 | E29: =SUM(C29+D29) -> 10 | F29: Miercoles | G29: =AVERAGE(Datos!H323:H331) -> 1965.5556 | I29: 0 | J29: 0 | K29: 0 | L29: 0 | M29: 0 | N29: 0 | O29: 0 | P29: 0 | Q29: 0 | R29: 1 | S29: 1 | T29: 1
A30: 45911 | B30: =SUM(Datos!H332:H338) -> 18790 | C30: =COUNTA(Datos!H332:H338) -> 7 | D30: 1 | E30: =SUM(C30+D30) -> 8 | F30: Jueves | G30: =AVERAGE(Datos!H332:H338) -> 2684.2857 | I30: 1 | J30: 0 | K30: 0 | L30: 0 | M30: 0 | N30: 0 | O30: 0 | P30: 0 | Q30: 0 | R30: 0 | S30: 0 | T30: 0
A31: 12//09/2025 | B31: =SUM(Datos!H339:H346) -> 22681 | C31: =COUNTA(Datos!H339:H346) -> 8 | D31: 5 | E31: =SUM(C31+D31) -> 13 | F31: Viernes | G31: =AVERAGE(Datos!H339:H346) -> 2835.125 | I31: 1 | J31: 1 | K31: 0 | L31: 0 | M31: 0 | N31: 0 | O31: 0 | P31: 0 | Q31: 0 | R31: 0 | S31: 0 | T31: 0
A32: 45914 | B32: =SUM(Datos!H347:H359) -> 32915 | C32: =COUNTA(Datos!H347:H359) -> 13 | D32: 1 | E32: =SUM(C32+D32) -> 14 | F32: Domingo | G32: =AVERAGE(Datos!H347:H359) -> 2531.9231 | I32: 0 | J32: 0 | K32: 0 | L32: 0 | M32: 1 | N32: 1 | O32: 1 | P32: 1 | Q32: 1 | R32: 0 | S32: 1 | T32: 0
A33: 45915 | B33: =SUM(Datos!H361:H361) -> 2580 | C33: =COUNTA(Datos!H361:H361) -> 1 | D33: 0 | E33: =SUM(C33+D33) -> 1 | F33: Lunes | G33: =AVERAGE(Datos!H361:H361) -> 2580 | I33: 0 | J33: 0 | K33: 0 | L33: 0 | M33: 0 | N33: 0 | O33: 1 | P33: 0 | Q33: 0 | R33: 0 | S33: 0 | T33: 0
A34: 45916 | B34: =SUM(Datos!H362:H374) -> 23715 | C34: =COUNTA(Datos!H362:H374) -> 13 | D34: 0 | E34: =SUM(C34+D34) -> 13 | F34: Martes | G34: =AVERAGE(Datos!H362:H374) -> 1824.2308 | I34: 0 | J34: 0 | K34: 0 | L34: 1 | M34: 1 | N34: 1 | O34: 1 | P34: 0 | Q34: 0 | R34: 0 | S34: 0 | T34: 0
A35: 45917 | B35: =SUM(Datos!H375:H382) -> 27001 | C35: =COUNTA(Datos!H375:H382) -> 8 | D35: 1 | E35: =SUM(C35+D35) -> 9 | F35: Miercoles | G35: =AVERAGE(Datos!H375:H382) -> 3375.125 | I35: 0 | J35: 0 | K35: 0 | L35: 0 | M35: 1 | N35: 1 | O35: 0 | P35: 0 | Q35: 0 | R35: 0 | S35: 0 | T35: 0
A36: 45918 | B36: =SUM(Datos!H383:H403) -> 49730 | C36: =COUNTA(Datos!H383:H403) -> 21 | D36: 4 | E36: =SUM(C36+D36) -> 25 | F36: Jueves | G36: =AVERAGE(Datos!H351:H363) -> 2400 | I36: 0 | J36: 0 | K36: 0 | L36: 1 | M36: 1 | N36: 1 | O36: 1 | P36: 1 | Q36: 1 | R36: 1 | S36: 1 | T36: 0
A37: 45919 | B37: =SUM(Datos!H404:H408) -> 15679 | C37: =COUNTA(Datos!H404:H408) -> 5 | D37: 2 | E37: =SUM(C37+D37) -> 7 | F37: Viernes | G37: =AVERAGE(Datos!H404:H408) -> 3135.8 | I37: 0 | J37: 0 | K37: 0 | L37: 0 | M37: 0 | N37: 0 | O37: 1 | P37: 1 | Q37: 0 | R37: 0 | S37: 0 | T37: 0
A38: 45920 | B38: =SUM(Datos!H409:H420) -> 45960 | C38: =COUNTA(Datos!H409:H420) -> 12 | D38: 2 | E38: =SUM(C38+D38) -> 14 | F38: Sabado | G38: =AVERAGE(Datos!H409:H420) -> 3830 | I38: 0 | J38: 0 | K38: 0 | L38: 0 | M38: 0 | N38: 0 | O38: 0 | P38: 0 | Q38: 1 | R38: 1 | S38: 1 | T38: 1
A39: 45924 | B39: =SUM(Datos!H421:H433) -> 32670 | C39: =COUNTA(Datos!H421:H433) -> 13 | D39: 4 | E39: =SUM(C39+D39) -> 17 | F39: Miercoles | G39: =AVERAGE(Datos!H421:H433) -> 2513.0769 | I39: 0 | J39: 0 | K39: 0 | L39: 0 | M39: 0 | N39: 0 | O39: 0 | P39: 0 | Q39: 1 | R39: 1 | S39: 1 | T39: 1
A40: 45926 | B40: =SUM(Datos!H434:H439) -> 9840 | C40: =COUNTA(Datos!H434:H439) -> 5 | D40: 0 | E40: =SUM(C40+D40) -> 5 | F40: =TEXT(A40,"DDDD") -> viernes | G40: =AVERAGE(Datos!H434:H439) -> 1968 | I40: 0 | J40: 0 | K40: 0 | L40: 0 | M40: 0 | N40: 0 | O40: 0 | P40: 1 | Q40: 1 | R40: 1 | S40: 1 | T40: 0
...

Sheet KPIs
A1: Métrica | B1: Valor
A2: Total Ingresos | B2: =SUM(Resumen_por_dia!B2:B90) -> 2797924.5
A3: Cantidad Pedidos | B3: =COUNTA(Datos!H2:H934) -> 931
A4: Ticket Promedio | B4: =AVERAGE(Datos!H2:H934) -> 2735.5956

Sheet Hoja1
A1: mes | B1: ingresos | C1: Dias Registrados
A2: Julio | B2: =SUM(Resumen_por_dia!B2:B5) -> 94827 | C2: =COUNTA(Resumen_por_dia!B2:B5) -> 4
A3: Agosto | B3: =SUM(Resumen_por_dia!B6:B19) -> 564881.88 | C3: =COUNTA(Resumen_por_dia!B6:B19) -> 14
A4: Septiembre | B4: =SUM(Resumen_por_dia!B20:B42) -> 514691 | C4: =COUNTA(Resumen_por_dia!B20:B42) -> 23
A5: Octubre | B5: =SUM(Resumen_por_dia!B43:B54) -> 467428 | C5: =COUNTA(Resumen_por_dia!B43:B54) -> 12
A6: Noviembre | B6: =SUM(Resumen_por_dia!B55:B65) -> 369253.4 | C6: =COUNTA(Resumen_por_dia!B54:B61) -> 8
A7: Diciembre | B7: =SUM(Resumen_por_dia!B66:B82) -> 516121.2 | C7: =COUNTA(Resumen_por_dia!B66:B82) -> 17
A8: Enero
A9: Febrero
A10: Marzo
A11: Abril
A12: Mayo
A13: Junio
A14: Julio
A15: Agosto
A16: Septiembre
A17: Octubre
A18: Noviembre
A19: Diciembre

Sheet Resumen_por_hora
A1: Fecha | B1: Hora_24h | C1: Total_Ingresos | D1: Cant_Pedidos
A2: 20 Agosto | B2: 16:21 | C2: 1980 | D2: 1
A3: 20 Agosto | B3: 16:54 | C3: 2720 | D3: 1
A4: 20 Agosto | B4: 17:20 | C4: 4120 | D4: 1
A5: 20 Agosto | B5: 17:50 | C5: 1620 | D5: 1
A6: 20 Agosto | B6: 18:11 | C6: 1260 | D6: 1
A7: 20 Agosto | B7: 18:33 | C7: 2240 | D7: 1
A8: 20 Agosto | B8: 18:47 | C8: 1261 | D8: 1
A9: 20 Agosto | B9: 19:23 | C9: 2840 | D9: 1
A10: 20 Agosto | B10: 19:37 | C10: 1260 | D10: 1
A11: 20 Agosto | B11: 20:18 | C11: 3900 | D11: 1
A12: 20 Agosto | B12: 20:27 | C12: 1790 | D12: 1
A13: 20 Agosto | B13: 20:58 | C13: 3240 | D13: 1
... A35: 21 Agosto | B35: 16:36 | C35: 1740 | D35: 1
